Workbook

Sheet Instrucciones
B2: EMPRESA METROPOLITANA DE TRANSPORTE LA CAROLINA
B3: Transporte con corazón · Comité Directivos · 26 de mayo de 2026
B5: PLANTILLA DE INICIATIVAS POR DEPARTAMENTO
B6: Iniciativas de Ahorro · Ingreso · Mixtas — Una hoja por departamento
B8: ¿CÓMO USAR ESTE ARCHIVO?
B10: 1. | C10: Cada jefe de departamento abre SU hoja (pestaña con el nombre de su área). Las iniciativas identificadas en la reunión ya están pre-cargadas.
B11: 2. | C11: Llene su nombre y la fecha en el encabezado. Luego complete los montos (pesimista, base, optimista) por iniciativa en las celdas amarillas.
B12: 3. | C12: Puede agregar nuevas iniciativas en las filas vacías al final. Use los menús desplegables para Tipo, Categoría y Estado.
B13: 4. | C13: Las columnas grises (Valor Esperado, Anual, Payback, ROI) se calculan automáticamente.
B14: 5. | C14: Diligencie también: Plan de implementación (hitos), KPIs de seguimiento, Firma.
B15: 6. | C15: La hoja «CONSOLIDADO» suma automáticamente todas las iniciativas de todos los departamentos.
B16: 7. | C16: Entrega: martes 2 de junio de 2026 — 5:00 PM. Presentación 10 min en comité del 9 de junio.
B17: 8. | C17: Anexe cotizaciones, contratos preliminares y referencias (mínimo 3 cotizaciones para cambios de proveedor).
B19: CÓDIGOS DE COLOR
C20: Llenar
C21: Automático
C22: Etiqueta
C23: Sección
B25: DEPARTAMENTOS (HOJAS DISPONIBLES)
B26: • | C26: Tesorería | F26: 4 iniciativas pre-cargadas
B27: • | C27: Contabilidad | F27: 7 iniciativas pre-cargadas
B28: • | C28: Mantenimiento y Compras | F28: 7 iniciativas pre-cargadas
B29: • | C29: Operaciones | F29: 5 iniciativas pre-cargadas
B30: • | C30: Comercial | F30: 5 iniciativas pre-cargadas
B31: • | C31: Tecnología (TI) | F31: 6 iniciativas pre-cargadas
B32: • | C32: Talento Humano | F32: 7 iniciativas pre-cargadas
B34: TRANSPORTE CON CORAZÓN · Ideas ejecutables · Planes medibles

Sheet Tesorería
A1: LA CAROLINA · METROPOLITANA DE TRANSPORTE
A2: DEPARTAMENTO: TESORERÍA
A3: Plantilla de iniciativas de ahorro e ingreso · Comité Directivos · 26 may 2026
A5: 1. DATOS DEL JEFE Y ENTREGA
A6: Jefe responsable | D6: Fecha entrega | G6: # Iniciativas | I6: Total ahorro/ingreso anual
G7: =COUNTA(B11:B25) -> 4 | I7: =SUM(I11:I25) -> 38374000
A9: 2. INICIATIVAS · LLENE LAS CELDAS AMARILLAS
A10: # | B10: Iniciativa | C10: Tipo | D10: Categoría | E10: Pesim. mes | F10: Base mes | G10: Optim. mes | H10: Esperado mes | I10: Anual esperado | J10: CapEx | K10: Payback (m) | L10: ROI 12m | M10: Estado | N10: Notas / Metodología
A11: 1 | B11: Cambio transportadora a Atlas | C11: AHORRO | D11: Cambio proveedor | E11: 3590000 | F11: 3590000 | G11: 3590000 | H11: =IFERROR(IF(OR(E11="",F11="",G11=""),0,ROUND((E11+4*F11+G11)/6,0)),0) -> 3590000 | I11: =H11*7 -> 25130000 | K11: =IFERROR(IF(AND(H11>0,J11>0),ROUND(J11/H11,1),"-"),"-") -> - | L11: =IFERROR(IF(J11>0,(I11-J11)/J11,""),"") | M11: Confirmado
A12: 2 | B12: Comisión ACH (BBVA → Banco Bogotá) disminucion 70% | C12: AHORRO | D12: Renegociación proveedor | E12: 772000 | F12: 772000 | G12: 772000 | H12: =IFERROR(IF(OR(E12="",F12="",G12=""),0,ROUND((E12+4*F12+G12)/6,0)),0) -> 772000 | I12: =H12*7 -> 5404000 | K12: =IFERROR(IF(AND(H12>0,J12>0),ROUND(J12/H12,1),"-"),"-") -> - | L12: =IFERROR(IF(J12>0,(I12-J12)/J12,""),"") | M12: Confirmado
A13: 3 | B13: Optimización GMF (4×1000 → 2×1000) | C13: AHORRO | D13: Renegociación proveedor | E13: 1120000 | F13: 1120000 | G13: 1120000 | H13: =IFERROR(IF(OR(E13="",F13="",G13=""),0,ROUND((E13+4*F13+G13)/6,0)),0) -> 1120000 | I13: =H13*7 -> 7840000 | K13: =IFERROR(IF(AND(H13>0,J13>0),ROUND(J13/H13,1),"-"),"-") -> - | L13: =IFERROR(IF(J13>0,(I13-J13)/J13,""),"") | M13: Confirmado
A14: 4 | B14: Digitalización de informes de afiliados — firma digital y trazabilidad | C14: AHORRO | D14: Digitalización | H14: =IFERROR(IF(OR(E14="",F14="",G14=""),0,ROUND((E14+4*F14+G14)/6,0)),0) -> 0 | I14: =H14*12 -> 0 | K14: =IFERROR(IF(AND(H14>0,J14>0),ROUND(J14/H14,1),"-"),"-") -> - | L14: =IFERROR(IF(J14>0,(I14-J14)/J14,""),"") | M14: En curso
A15: 5 | H15: =IFERROR(IF(OR(E15="",F15="",G15=""),0,ROUND((E15+4*F15+G15)/6,0)),0) -> 0 | I15: =H15*12 -> 0 | K15: =IFERROR(IF(AND(H15>0,J15>0),ROUND(J15/H15,1),"-"),"-") -> - | L15: =IFERROR(IF(J15>0,(I15-J15)/J15,""),"")
A16: 6 | H16: =IFERROR(IF(OR(E16="",F16="",G16=""),0,ROUND((E16+4*F16+G16)/6,0)),0) -> 0 | I16: =H16*12 -> 0 | K16: =IFERROR(IF(AND(H16>0,J16>0),ROUND(J16/H16,1),"-"),"-") -> - | L16: =IFERROR(IF(J16>0,(I16-J16)/J16,""),"")
A17: 7 | H17: =IFERROR(IF(OR(E17="",F17="",G17=""),0,ROUND((E17+4*F17+G17)/6,0)),0) -> 0 | I17: =H17*12 -> 0 | K17: =IFERROR(IF(AND(H17>0,J17>0),ROUND(J17/H17,1),"-"),"-") -> - | L17: =IFERROR(IF(J17>0,(I17-J17)/J17,""),"")
A18: 8 | H18: =IFERROR(IF(OR(E18="",F18="",G18=""),0,ROUND((E18+4*F18+G18)/6,0)),0) -> 0 | I18: =H18*12 -> 0 | K18: =IFERROR(IF(AND(H18>0,J18>0),ROUND(J18/H18,1),"-"),"-") -> - | L18: =IFERROR(IF(J18>0,(I18-J18)/J18,""),"")
A19: 9 | H19: =IFERROR(IF(OR(E19="",F19="",G19=""),0,ROUND((E19+4*F19+G19)/6,0)),0) -> 0 | I19: =H19*12 -> 0 | K19: =IFERROR(IF(AND(H19>0,J19>0),ROUND(J19/H19,1),"-"),"-") -> - | L19: =IFERROR(IF(J19>0,(I19-J19)/J19,""),"")
A20: 10 | H20: =IFERROR(IF(OR(E20="",F20="",G20=""),0,ROUND((E20+4*F20+G20)/6,0)),0) -> 0 | I20: =H20*12 -> 0 | K20: =IFERROR(IF(AND(H20>0,J20>0),ROUND(J20/H20,1),"-"),"-") -> - | L20: =IFERROR(IF(J20>0,(I20-J20)/J20,""),"")
A21: 11 | H21: =IFERROR(IF(OR(E21="",F21="",G21=""),0,ROUND((E21+4*F21+G21)/6,0)),0) -> 0 | I21: =H21*12 -> 0 | K21: =IFERROR(IF(AND(H21>0,J21>0),ROUND(J21/H21,1),"-"),"-") -> - | L21: =IFERROR(IF(J21>0,(I21-J21)/J21,""),"")
A22: 12 | H22: =IFERROR(IF(OR(E22="",F22="",G22=""),0,ROUND((E22+4*F22+G22)/6,0)),0) -> 0 | I22: =H22*12 -> 0 | K22: =IFERROR(IF(AND(H22>0,J22>0),ROUND(J22/H22,1),"-"),"-") -> - | L22: =IFERROR(IF(J22>0,(I22-J22)/J22,""),"")
A23: 13 | H23: =IFERROR(IF(OR(E23="",F23="",G23=""),0,ROUND((E23+4*F23+G23)/6,0)),0) -> 0 | I23: =H23*12 -> 0 | K23: =IFERROR(IF(AND(H23>0,J23>0),ROUND(J23/H23,1),"-"),"-") -> - | L23: =IFERROR(IF(J23>0,(I23-J23)/J23,""),"")
A24: 14 | H24: =IFERROR(IF(OR(E24="",F24="",G24=""),0,ROUND((E24+4*F24+G24)/6,0)),0) -> 0 | I24: =H24*12 -> 0 | K24: =IFERROR(IF(AND(H24>0,J24>0),ROUND(J24/H24,1),"-"),"-") -> - | L24: =IFERROR(IF(J24>0,(I24-J24)/J24,""),"")
A25: 15 | H25: =IFERROR(IF(OR(E25="",F25="",G25=""),0,ROUND((E25+4*F25+G25)/6,0)),0) -> 0 | I25: =H25*12 -> 0 | K25: =IFERROR(IF(AND(H25>0,J25>0),ROUND(J25/H25,1),"-"),"-") -> - | L25: =IFERROR(IF(J25>0,(I25-J25)/J25,""),"")
A26: TOTAL DEPARTAMENTO | E26: =SUM(E11:E25) -> 5482000 | F26: =SUM(F11:F25) -> 5482000 | G26: =SUM(G11:G25) -> 5482000 | H26: =SUM(H11:H25) -> 5482000 | I26: =SUM(I11:I25) -> 38374000 | J26: =SUM(J11:J25) -> 0
A28: 3. PLAN DE IMPLEMENTACIÓN · HITOS PRINCIPALES
A29: # | B29: Hito / acción | H29: Responsable | K29: Fecha objetivo | M29: Estado
A30: 1
A31: 2
A32: 3
A33: 4
A34: 5
A35: 6
A37: 4. KPIs DE SEGUIMIENTO MENSUAL
A38: KPI | F38: Línea base | I38: Meta mensual | L38: Frecuencia
A39: Accidentalidad (eventos/mes) | L39: Mensual
A40: Rotación de personal | L40: Mensual
A41: Ausentismo de conductores | L41: Mensual
A42: Conductores tarde | L42: Mensual
A43: Ahorro materializado vs. proyectado | L43: Mensual
A48: 5. COMPROMISO Y FIRMA
...

Sheet Contabilidad
A1: LA CAROLINA · METROPOLITANA DE TRANSPORTE
A2: DEPARTAMENTO: CONTABILIDAD
A3: Plantilla de iniciativas de ahorro e ingreso · Comité Directivos · 26 may 2026
A5: 1. DATOS DEL JEFE Y ENTREGA
A6: Jefe responsable | D6: Fecha entrega | G6: # Iniciativas | I6: Total ahorro/ingreso anual
G7: =COUNTA(B11:B25) -> 7 | I7: =SUM(I11:I25) -> 75678396
A9: 2. INICIATIVAS · LLENE LAS CELDAS AMARILLAS
A10: # | B10: Iniciativa | C10: Tipo | D10: Categoría | E10: Pesim. mes | F10: Base mes | G10: Optim. mes | H10: Esperado mes | I10: Anual esperado | J10: CapEx | K10: Payback (m) | L10: ROI 12m | M10: Estado | N10: Notas / Metodología
A11: 1 | B11: Ahorro porcentual en impuestos — revisión software contable y tributario | C11: AHORRO | D11: Optimización proceso | H11: =IFERROR(IF(OR(E11="",F11="",G11=""),0,ROUND((E11+4*F11+G11)/6,0)),0) -> 0 | I11: =H11*12 -> 0 | K11: =IFERROR(IF(AND(H11>0,J11>0),ROUND(J11/H11,1),"-"),"-") -> - | L11: =IFERROR(IF(J11>0,(I11-J11)/J11,""),"") | M11: Análisis
A12: 2 | B12: Reducción consumo de papel + digitalización archivo muerto | C12: AHORRO | D12: Digitalización | H12: =IFERROR(IF(OR(E12="",F12="",G12=""),0,ROUND((E12+4*F12+G12)/6,0)),0) -> 0 | I12: =H12*12 -> 0 | K12: =IFERROR(IF(AND(H12>0,J12>0),ROUND(J12/H12,1),"-"),"-") -> - | L12: =IFERROR(IF(J12>0,(I12-J12)/J12,""),"") | M12: Análisis
A13: 3 | B13: Implementación de firma digital corporativa | C13: AHORRO | D13: Digitalización | H13: =IFERROR(IF(OR(E13="",F13="",G13=""),0,ROUND((E13+4*F13+G13)/6,0)),0) -> 0 | I13: =H13*12 -> 0 | K13: =IFERROR(IF(AND(H13>0,J13>0),ROUND(J13/H13,1),"-"),"-") -> - | L13: =IFERROR(IF(J13>0,(I13-J13)/J13,""),"") | M13: Propuesta
A14: 4 | B14: Beneficios tributarios autos a GAS (IVA, retención, renta) — Edith | C14: AHORRO | D14: Optimización proceso | E14: 5833333 | F14: 5833333 | G14: 5833333 | H14: =IFERROR(IF(OR(E14="",F14="",G14=""),0,ROUND((E14+4*F14+G14)/6,0)),0) -> 5833333 | I14: =H14*12 -> 69999996 | K14: =IFERROR(IF(AND(H14>0,J14>0),ROUND(J14/H14,1),"-"),"-") -> - | L14: =IFERROR(IF(J14>0,(I14-J14)/J14,""),"") | M14: Análisis
A15: 5 | B15: Reducción de horas extras (operativo y mantenimiento) | C15: AHORRO | D15: Optimización proceso | H15: =IFERROR(IF(OR(E15="",F15="",G15=""),0,ROUND((E15+4*F15+G15)/6,0)),0) -> 0 | I15: =H15*12 -> 0 | K15: =IFERROR(IF(AND(H15>0,J15>0),ROUND(J15/H15,1),"-"),"-") -> - | L15: =IFERROR(IF(J15>0,(I15-J15)/J15,""),"") | M15: En análisis
A16: 6 | B16: Revisión horas sábados — anticipación reducción jornada (Jorge, John, Edith) | C16: AHORRO | D16: Optimización proceso | E16: 300000 | F16: 300000 | G16: 300000 | H16: =IFERROR(IF(OR(E16="",F16="",G16=""),0,ROUND((E16+4*F16+G16)/6,0)),0) -> 300000 | I16: =H16*12 -> 3600000 | K16: =IFERROR(IF(AND(H16>0,J16>0),ROUND(J16/H16,1),"-"),"-") -> - | L16: =IFERROR(IF(J16>0,(I16-J16)/J16,""),"") | M16: En análisis
A17: 7 | B17: Migración a facturación electrónica gratuita DIAN | C17: AHORRO | D17: Digitalización | E17: =41800+131400 -> 173200 | F17: 173200 | G17: 173200 | H17: =IFERROR(IF(OR(E17="",F17="",G17=""),0,ROUND((E17+4*F17+G17)/6,0)),0) -> 173200 | I17: =H17*12 -> 2078400 | K17: =IFERROR(IF(AND(H17>0,J17>0),ROUND(J17/H17,1),"-"),"-") -> - | L17: =IFERROR(IF(J17>0,(I17-J17)/J17,""),"") | M17: En análisis
A18: 8 | H18: =IFERROR(IF(OR(E18="",F18="",G18=""),0,ROUND((E18+4*F18+G18)/6,0)),0) -> 0 | I18: =H18*12 -> 0 | K18: =IFERROR(IF(AND(H18>0,J18>0),ROUND(J18/H18,1),"-"),"-") -> - | L18: =IFERROR(IF(J18>0,(I18-J18)/J18,""),"")
A19: 9 | H19: =IFERROR(IF(OR(E19="",F19="",G19=""),0,ROUND((E19+4*F19+G19)/6,0)),0) -> 0 | I19: =H19*12 -> 0 | K19: =IFERROR(IF(AND(H19>0,J19>0),ROUND(J19/H19,1),"-"),"-") -> - | L19: =IFERROR(IF(J19>0,(I19-J19)/J19,""),"")
A20: 10 | H20: =IFERROR(IF(OR(E20="",F20="",G20=""),0,ROUND((E20+4*F20+G20)/6,0)),0) -> 0 | I20: =H20*12 -> 0 | K20: =IFERROR(IF(AND(H20>0,J20>0),ROUND(J20/H20,1),"-"),"-") -> - | L20: =IFERROR(IF(J20>0,(I20-J20)/J20,""),"")
A21: 11 | H21: =IFERROR(IF(OR(E21="",F21="",G21=""),0,ROUND((E21+4*F21+G21)/6,0)),0) -> 0 | I21: =H21*12 -> 0 | K21: =IFERROR(IF(AND(H21>0,J21>0),ROUND(J21/H21,1),"-"),"-") -> - | L21: =IFERROR(IF(J21>0,(I21-J21)/J21,""),"")
A22: 12 | H22: =IFERROR(IF(OR(E22="",F22="",G22=""),0,ROUND((E22+4*F22+G22)/6,0)),0) -> 0 | I22: =H22*12 -> 0 | K22: =IFERROR(IF(AND(H22>0,J22>0),ROUND(J22/H22,1),"-"),"-") -> - | L22: =IFERROR(IF(J22>0,(I22-J22)/J22,""),"")
A23: 13 | H23: =IFERROR(IF(OR(E23="",F23="",G23=""),0,ROUND((E23+4*F23+G23)/6,0)),0) -> 0 | I23: =H23*12 -> 0 | K23: =IFERROR(IF(AND(H23>0,J23>0),ROUND(J23/H23,1),"-"),"-") -> - | L23: =IFERROR(IF(J23>0,(I23-J23)/J23,""),"")
A24: 14 | H24: =IFERROR(IF(OR(E24="",F24="",G24=""),0,ROUND((E24+4*F24+G24)/6,0)),0) -> 0 | I24: =H24*12 -> 0 | K24: =IFERROR(IF(AND(H24>0,J24>0),ROUND(J24/H24,1),"-"),"-") -> - | L24: =IFERROR(IF(J24>0,(I24-J24)/J24,""),"")
A25: 15 | H25: =IFERROR(IF(OR(E25="",F25="",G25=""),0,ROUND((E25+4*F25+G25)/6,0)),0) -> 0 | I25: =H25*12 -> 0 | K25: =IFERROR(IF(AND(H25>0,J25>0),ROUND(J25/H25,1),"-"),"-") -> - | L25: =IFERROR(IF(J25>0,(I25-J25)/J25,""),"")
A26: TOTAL DEPARTAMENTO | E26: =SUM(E11:E25) -> 6306533 | F26: =SUM(F11:F25) -> 6306533 | G26: =SUM(G11:G25) -> 6306533 | H26: =SUM(H11:H25) -> 6306533 | I26: =SUM(I11:I25) -> 75678396 | J26: =SUM(J11:J25) -> 0
A28: 3. PLAN DE IMPLEMENTACIÓN · HITOS PRINCIPALES
A29: # | B29: Hito / acción | H29: Responsable | K29: Fecha objetivo | M29: Estado
A30: 1
A31: 2
A32: 3
A33: 4
A34: 5
A35: 6
A37: 4. KPIs DE SEGUIMIENTO MENSUAL
A38: KPI | F38: Línea base | I38: Meta mensual | L38: Frecuencia
A39: Accidentalidad (eventos/mes) | L39: Mensual
A40: Rotación de personal | L40: Mensual
A41: Ausentismo de conductores | L41: Mensual
A42: Conductores tarde | L42: Mensual
A43: Ahorro materializado vs. proyectado | L43: Mensual
A48: 5. COMPROMISO Y FIRMA
...

Sheet Mantenimiento y Compras
A1: LA CAROLINA · METROPOLITANA DE TRANSPORTE
A2: DEPARTAMENTO: MANTENIMIENTO Y COMPRAS
A3: Plantilla de iniciativas de ahorro e ingreso · Comité Directivos · 26 may 2026
A5: 1. DATOS DEL JEFE Y ENTREGA
A6: Jefe responsable | D6: Fecha entrega | G6: # Iniciativas | I6: Total ahorro/ingreso anual
G7: =COUNTA(B11:B25) -> 9 | I7: =SUM(I11:I25) -> 74093466
A9: 2. INICIATIVAS · LLENE LAS CELDAS AMARILLAS
A10: # | B10: Iniciativa | C10: Tipo | D10: Categoría | E10: Pesim. mes | F10: Base mes | G10: Optim. mes | H10: Esperado mes | I10: Anual esperado | J10: CapEx | K10: Payback (m) | L10: ROI 12m | M10: Estado | N10: Notas / Metodología
A11: 1 | B11: Reducción consolidada de repuestos (34.5% vs. 2026) | C11: AHORRO | D11: Renegociación proveedor | H11: =IFERROR(IF(OR(E11="",F11="",G11=""),0,ROUND((E11+4*F11+G11)/6,0)),0) -> 0 | I11: =H11*12 -> 0 | K11: =IFERROR(IF(AND(H11>0,J11>0),ROUND(J11/H11,1),"-"),"-") -> - | L11: =IFERROR(IF(J11>0,(I11-J11)/J11,""),"") | M11: Materializado
A12: 2 | B12: Sistema de inyección — ahorro acumulado | C12: AHORRO | D12: Cambio proveedor | E12: 916667 | F12: 916667 | G12: 916667 | H12: =IFERROR(IF(OR(E12="",F12="",G12=""),0,ROUND((E12+4*F12+G12)/6,0)),0) -> 916667 | I12: =H12*12 -> 11000004 | K12: =IFERROR(IF(AND(H12>0,J12>0),ROUND(J12/H12,1),"-"),"-") -> - | L12: =IFERROR(IF(J12>0,(I12-J12)/J12,""),"") | M12: Materializado
A13: 3 | B13: Alternadores — de $780k a $250k (18 unidades) | C13: AHORRO | D13: Cambio proveedor | E13: 800000 | F13: 800000 | G13: 800000 | H13: =IFERROR(IF(OR(E13="",F13="",G13=""),0,ROUND((E13+4*F13+G13)/6,0)),0) -> 800000 | I13: =H13*12 -> 9600000 | K13: =IFERROR(IF(AND(H13>0,J13>0),ROUND(J13/H13,1),"-"),"-") -> - | L13: =IFERROR(IF(J13>0,(I13-J13)/J13,""),"") | M13: Materializado
A14: 4 | B14: Renegociación proveedores — metodología mínimo 3 cotizaciones | C14: AHORRO | D14: Renegociación proveedor | H14: =IFERROR(IF(OR(E14="",F14="",G14=""),0,ROUND((E14+4*F14+G14)/6,0)),0) -> 0 | I14: =H14*12 -> 0 | K14: =IFERROR(IF(AND(H14>0,J14>0),ROUND(J14/H14,1),"-"),"-") -> - | L14: =IFERROR(IF(J14>0,(I14-J14)/J14,""),"") | M14: En curso
A15: 5 | B15: Mejoramiento / reducción de horas extras del área | C15: AHORRO | D15: Optimización proceso | H15: =IFERROR(IF(OR(E15="",F15="",G15=""),0,ROUND((E15+4*F15+G15)/6,0)),0) -> 0 | I15: =H15*12 -> 0 | K15: =IFERROR(IF(AND(H15>0,J15>0),ROUND(J15/H15,1),"-"),"-") -> - | L15: =IFERROR(IF(J15>0,(I15-J15)/J15,""),"") | M15: Propuesta
A16: 6 | B16: Plan renovación de celulares y equipos — listado activos + renegociación (Helmut/Cindy) | C16: AHORRO | D16: Tecnología | H16: =IFERROR(IF(OR(E16="",F16="",G16=""),0,ROUND((E16+4*F16+G16)/6,0)),0) -> 0 | I16: =H16*12 -> 0 | K16: =IFERROR(IF(AND(H16>0,J16>0),ROUND(J16/H16,1),"-"),"-") -> - | L16: =IFERROR(IF(J16>0,(I16-J16)/J16,""),"") | M16: Por desarrollar
A17: 7 | B17: Aplicativo de alertas de repuestos repetitivos | C17: AHORRO | D17: Tecnología | H17: =IFERROR(IF(OR(E17="",F17="",G17=""),0,ROUND((E17+4*F17+G17)/6,0)),0) -> 0 | I17: =H17*12 -> 0 | K17: =IFERROR(IF(AND(H17>0,J17>0),ROUND(J17/H17,1),"-"),"-") -> - | L17: =IFERROR(IF(J17>0,(I17-J17)/J17,""),"") | M17: Por desarrollar
A18: 8 | B18: Urea automotriz de $6341 a $3900 | C18: AHORRO | D18: CAMBIO DE MODELO | E18: 2730006 | F18: 2730006 | G18: 2730006 | H18: 2730006 | I18: =H18*7 -> 19110042 | K18: =IFERROR(IF(AND(H18>0,J18>0),ROUND(J18/H18,1),"-"),"-") -> - | L18: =IFERROR(IF(J18>0,(I18-J18)/J18,""),"") | M18: Propuesta
A19: 9 | B19: Valor referencia DIESEL hoy $11251 | C19: AHORRO | D19: Renegociación proveedor | E19: 4969600 | F19: 5730570 | G19: 6522600 | H19: 5730570 | I19: =H19*6 -> 34383420 | K19: =IFERROR(IF(AND(H19>0,J19>0),ROUND(J19/H19,1),"-"),"-") -> - | L19: =IFERROR(IF(J19>0,(I19-J19)/J19,""),"") | M19: Propuesta
A20: 10 | H20: =IFERROR(IF(OR(E20="",F20="",G20=""),0,ROUND((E20+4*F20+G20)/6,0)),0) -> 0 | I20: =H20*12 -> 0 | K20: =IFERROR(IF(AND(H20>0,J20>0),ROUND(J20/H20,1),"-"),"-") -> - | L20: =IFERROR(IF(J20>0,(I20-J20)/J20,""),"")
A21: 11 | H21: =IFERROR(IF(OR(E21="",F21="",G21=""),0,ROUND((E21+4*F21+G21)/6,0)),0) -> 0 | I21: =H21*12 -> 0 | K21: =IFERROR(IF(AND(H21>0,J21>0),ROUND(J21/H21,1),"-"),"-") -> - | L21: =IFERROR(IF(J21>0,(I21-J21)/J21,""),"")
A22: 12 | H22: =IFERROR(IF(OR(E22="",F22="",G22=""),0,ROUND((E22+4*F22+G22)/6,0)),0) -> 0 | I22: =H22*12 -> 0 | K22: =IFERROR(IF(AND(H22>0,J22>0),ROUND(J22/H22,1),"-"),"-") -> - | L22: =IFERROR(IF(J22>0,(I22-J22)/J22,""),"")
A23: 13 | H23: =IFERROR(IF(OR(E23="",F23="",G23=""),0,ROUND((E23+4*F23+G23)/6,0)),0) -> 0 | I23: =H23*12 -> 0 | K23: =IFERROR(IF(AND(H23>0,J23>0),ROUND(J23/H23,1),"-"),"-") -> - | L23: =IFERROR(IF(J23>0,(I23-J23)/J23,""),"")
A24: 14 | H24: =IFERROR(IF(OR(E24="",F24="",G24=""),0,ROUND((E24+4*F24+G24)/6,0)),0) -> 0 | I24: =H24*12 -> 0 | K24: =IFERROR(IF(AND(H24>0,J24>0),ROUND(J24/H24,1),"-"),"-") -> - | L24: =IFERROR(IF(J24>0,(I24-J24)/J24,""),"")
A25: 15 | H25: =IFERROR(IF(OR(E25="",F25="",G25=""),0,ROUND((E25+4*F25+G25)/6,0)),0) -> 0 | I25: =H25*12 -> 0 | K25: =IFERROR(IF(AND(H25>0,J25>0),ROUND(J25/H25,1),"-"),"-") -> - | L25: =IFERROR(IF(J25>0,(I25-J25)/J25,""),"")
A26: TOTAL DEPARTAMENTO | E26: =SUM(E11:E25) -> 9416273 | F26: =SUM(F11:F25) -> 10177243 | G26: =SUM(G11:G25) -> 10969273 | H26: =SUM(H11:H25) -> 10177243 | I26: =SUM(I11:I25) -> 74093466 | J26: =SUM(J11:J25) -> 0
A28: 3. PLAN DE IMPLEMENTACIÓN · HITOS PRINCIPALES
A29: # | B29: Hito / acción | H29: Responsable | K29: Fecha objetivo | M29: Estado
A30: 1
A31: 2
A32: 3
A33: 4
A34: 5
A35: 6
A37: 4. KPIs DE SEGUIMIENTO MENSUAL
A38: KPI | F38: Línea base | I38: Meta mensual | L38: Frecuencia
A39: Accidentalidad (eventos/mes) | L39: Mensual
A40: Rotación de personal | L40: Mensual
A41: Ausentismo de conductores | L41: Mensual
A42: Conductores tarde | L42: Mensual
A43: Ahorro materializado vs. proyectado | L43: Mensual
A48: 5. COMPROMISO Y FIRMA
...

Sheet Operaciones
A1: LA CAROLINA · METROPOLITANA DE TRANSPORTE
A2: DEPARTAMENTO: OPERACIONES
A3: Plantilla de iniciativas de ahorro e ingreso · Comité Directivos · 26 may 2026
A5: 1. DATOS DEL JEFE Y ENTREGA
A6: Jefe responsable | D6: Fecha entrega | G6: # Iniciativas | I6: Total ahorro/ingreso anual
G7: =COUNTA(B11:B25) -> 5 | I7: =SUM(I11:I25) -> 301218000
A9: 2. INICIATIVAS · LLENE LAS CELDAS AMARILLAS
A10: # | B10: Iniciativa | C10: Tipo | D10: Categoría | E10: Pesim. mes | F10: Base mes | G10: Optim. mes | H10: Esperado mes | I10: Anual esperado | J10: CapEx | K10: Payback (m) | L10: ROI 12m | M10: Estado | N10: Notas / Metodología
A11: 1 | B11: Proyecto Helmut — ahorro combustible y optimización de rutas (entrega 9 jun) | C11: MIXTA | D11: Optimización proceso | E11: 22493000 | F11: 25000000 | G11: 28116000 | H11: =IFERROR(IF(OR(E11="",F11="",G11=""),0,ROUND((E11+4*F11+G11)/6,0)),0) -> 25101500 | I11: =H11*12 -> 301218000 | K11: =IFERROR(IF(AND(H11>0,J11>0),ROUND(J11/H11,1),"-"),"-") -> - | L11: =IFERROR(IF(J11>0,(I11-J11)/J11,""),"") | M11: En análisis
A12: 2 | B12: Piloto Miramar — 48-50 vehículos, 3 viajes/vehículo, frecuencia 4-5 min | C12: MIXTA | D12: Optimización proceso | H12: =IFERROR(IF(OR(E12="",F12="",G12=""),0,ROUND((E12+4*F12+G12)/6,0)),0) -> 0 | I12: =H12*12 -> 0 | K12: =IFERROR(IF(AND(H12>0,J12>0),ROUND(J12/H12,1),"-"),"-") -> - | L12: =IFERROR(IF(J12>0,(I12-J12)/J12,""),"") | M12: Diseño
A13: 3 | B13: Plan de operaciones — mejoramiento del servicio (puntualidad, UX, seguridad) | C13: INGRESO | D13: Nueva fuente ingreso | H13: =IFERROR(IF(OR(E13="",F13="",G13=""),0,ROUND((E13+4*F13+G13)/6,0)),0) -> 0 | I13: =H13*12 -> 0 | K13: =IFERROR(IF(AND(H13>0,J13>0),ROUND(J13/H13,1),"-"),"-") -> - | L13: =IFERROR(IF(J13>0,(I13-J13)/J13,""),"") | M13: Diseño
A14: 4 | B14: Ruta Alameda-circunvalar-cra 38-centro — gestión Área Metropolitana (Dr. Fabio) | C14: INGRESO | D14: Nueva fuente ingreso | H14: =IFERROR(IF(OR(E14="",F14="",G14=""),0,ROUND((E14+4*F14+G14)/6,0)),0) -> 0 | I14: =H14*12 -> 0 | K14: =IFERROR(IF(AND(H14>0,J14>0),ROUND(J14/H14,1),"-"),"-") -> - | L14: =IFERROR(IF(J14>0,(I14-J14)/J14,""),"") | M14: Gestión
A15: 5 | B15: Incremento de usuarios — segmentos universidad/hospital · app Buzii | C15: INGRESO | D15: Nueva fuente ingreso | H15: =IFERROR(IF(OR(E15="",F15="",G15=""),0,ROUND((E15+4*F15+G15)/6,0)),0) -> 0 | I15: =H15*12 -> 0 | K15: =IFERROR(IF(AND(H15>0,J15>0),ROUND(J15/H15,1),"-"),"-") -> - | L15: =IFERROR(IF(J15>0,(I15-J15)/J15,""),"") | M15: Propuesta
A16: 6 | H16: =IFERROR(IF(OR(E16="",F16="",G16=""),0,ROUND((E16+4*F16+G16)/6,0)),0) -> 0 | I16: =H16*12 -> 0 | K16: =IFERROR(IF(AND(H16>0,J16>0),ROUND(J16/H16,1),"-"),"-") -> - | L16: =IFERROR(IF(J16>0,(I16-J16)/J16,""),"")
A17: 7 | H17: =IFERROR(IF(OR(E17="",F17="",G17=""),0,ROUND((E17+4*F17+G17)/6,0)),0) -> 0 | I17: =H17*12 -> 0 | K17: =IFERROR(IF(AND(H17>0,J17>0),ROUND(J17/H17,1),"-"),"-") -> - | L17: =IFERROR(IF(J17>0,(I17-J17)/J17,""),"")
A18: 8 | H18: =IFERROR(IF(OR(E18="",F18="",G18=""),0,ROUND((E18+4*F18+G18)/6,0)),0) -> 0 | I18: =H18*12 -> 0 | K18: =IFERROR(IF(AND(H18>0,J18>0),ROUND(J18/H18,1),"-"),"-") -> - | L18: =IFERROR(IF(J18>0,(I18-J18)/J18,""),"")
A19: 9 | H19: =IFERROR(IF(OR(E19="",F19="",G19=""),0,ROUND((E19+4*F19+G19)/6,0)),0) -> 0 | I19: =H19*12 -> 0 | K19: =IFERROR(IF(AND(H19>0,J19>0),ROUND(J19/H19,1),"-"),"-") -> - | L19: =IFERROR(IF(J19>0,(I19-J19)/J19,""),"")
A20: 10 | H20: =IFERROR(IF(OR(E20="",F20="",G20=""),0,ROUND((E20+4*F20+G20)/6,0)),0) -> 0 | I20: =H20*12 -> 0 | K20: =IFERROR(IF(AND(H20>0,J20>0),ROUND(J20/H20,1),"-"),"-") -> - | L20: =IFERROR(IF(J20>0,(I20-J20)/J20,""),"")
A21: 11 | H21: =IFERROR(IF(OR(E21="",F21="",G21=""),0,ROUND((E21+4*F21+G21)/6,0)),0) -> 0 | I21: =H21*12 -> 0 | K21: =IFERROR(IF(AND(H21>0,J21>0),ROUND(J21/H21,1),"-"),"-") -> - | L21: =IFERROR(IF(J21>0,(I21-J21)/J21,""),"")
A22: 12 | H22: =IFERROR(IF(OR(E22="",F22="",G22=""),0,ROUND((E22+4*F22+G22)/6,0)),0) -> 0 | I22: =H22*12 -> 0 | K22: =IFERROR(IF(AND(H22>0,J22>0),ROUND(J22/H22,1),"-"),"-") -> - | L22: =IFERROR(IF(J22>0,(I22-J22)/J22,""),"")
A23: 13 | H23: =IFERROR(IF(OR(E23="",F23="",G23=""),0,ROUND((E23+4*F23+G23)/6,0)),0) -> 0 | I23: =H23*12 -> 0 | K23: =IFERROR(IF(AND(H23>0,J23>0),ROUND(J23/H23,1),"-"),"-") -> - | L23: =IFERROR(IF(J23>0,(I23-J23)/J23,""),"")
A24: 14 | H24: =IFERROR(IF(OR(E24="",F24="",G24=""),0,ROUND((E24+4*F24+G24)/6,0)),0) -> 0 | I24: =H24*12 -> 0 | K24: =IFERROR(IF(AND(H24>0,J24>0),ROUND(J24/H24,1),"-"),"-") -> - | L24: =IFERROR(IF(J24>0,(I24-J24)/J24,""),"")
A25: 15 | H25: =IFERROR(IF(OR(E25="",F25="",G25=""),0,ROUND((E25+4*F25+G25)/6,0)),0) -> 0 | I25: =H25*12 -> 0 | K25: =IFERROR(IF(AND(H25>0,J25>0),ROUND(J25/H25,1),"-"),"-") -> - | L25: =IFERROR(IF(J25>0,(I25-J25)/J25,""),"")
A26: TOTAL DEPARTAMENTO | E26: =SUM(E11:E25) -> 22493000 | F26: =SUM(F11:F25) -> 25000000 | G26: =SUM(G11:G25) -> 28116000 | H26: =SUM(H11:H25) -> 25101500 | I26: =SUM(I11:I25) -> 301218000 | J26: =SUM(J11:J25) -> 0
A28: 3. PLAN DE IMPLEMENTACIÓN · HITOS PRINCIPALES
A29: # | B29: Hito / acción | H29: Responsable | K29: Fecha objetivo | M29: Estado
A30: 1
A31: 2
A32: 3
A33: 4
A34: 5
A35: 6
A37: 4. KPIs DE SEGUIMIENTO MENSUAL
A38: KPI | F38: Línea base | I38: Meta mensual | L38: Frecuencia
A39: Accidentalidad (eventos/mes) | L39: Mensual
A40: Rotación de personal | L40: Mensual
A41: Ausentismo de conductores | L41: Mensual
A42: Conductores tarde | L42: Mensual
A43: Ahorro materializado vs. proyectado | L43: Mensual
A48: 5. COMPROMISO Y FIRMA
...

Sheet Comercial
A1: LA CAROLINA · METROPOLITANA DE TRANSPORTE
A2: DEPARTAMENTO: COMERCIAL
A3: Plantilla de iniciativas de ahorro e ingreso · Comité Directivos · 26 may 2026
A5: 1. DATOS DEL JEFE Y ENTREGA
A6: Jefe responsable | D6: Fecha entrega | G6: # Iniciativas | I6: Total ahorro/ingreso anual
G7: =COUNTA(B11:B25) -> 5 | I7: =SUM(I11:I25) -> 0
A9: 2. INICIATIVAS · LLENE LAS CELDAS AMARILLAS
A10: # | B10: Iniciativa | C10: Tipo | D10: Categoría | E10: Pesim. mes | F10: Base mes | G10: Optim. mes | H10: Esperado mes | I10: Anual esperado | J10: CapEx | K10: Payback (m) | L10: ROI 12m | M10: Estado | N10: Notas / Metodología
A11: 1 | B11: Publimedios — pantallas publicitarias en buses (piloto 2 MS + 2 fotón) | C11: INGRESO | D11: Nueva fuente ingreso | H11: =IFERROR(IF(OR(E11="",F11="",G11=""),0,ROUND((E11+4*F11+G11)/6,0)),0) -> 0 | I11: =H11*12 -> 0 | K11: =IFERROR(IF(AND(H11>0,J11>0),ROUND(J11/H11,1),"-"),"-") -> - | L11: =IFERROR(IF(J11>0,(I11-J11)/J11,""),"") | M11: Piloto
A12: 2 | B12: Servicios B2B / Corporativos — escolar, eventos, EPS/ARL | C12: INGRESO | D12: B2B / Corporativo | H12: =IFERROR(IF(OR(E12="",F12="",G12=""),0,ROUND((E12+4*F12+G12)/6,0)),0) -> 0 | I12: =H12*12 -> 0 | K12: =IFERROR(IF(AND(H12>0,J12>0),ROUND(J12/H12,1),"-"),"-") -> - | L12: =IFERROR(IF(J12>0,(I12-J12)/J12,""),"") | M12: Propuesta
A13: 3 | B13: Monetización redes Instagram/Facebook (Cámara de Comercio completada) | C13: INGRESO | D13: Monetización activos | H13: =IFERROR(IF(OR(E13="",F13="",G13=""),0,ROUND((E13+4*F13+G13)/6,0)),0) -> 0 | I13: =H13*12 -> 0 | K13: =IFERROR(IF(AND(H13>0,J13>0),ROUND(J13/H13,1),"-"),"-") -> - | L13: =IFERROR(IF(J13>0,(I13-J13)/J13,""),"") | M13: Propuesta
A14: 4 | B14: Negociar con Ismael — mitad posts por mitad precio | C14: AHORRO | D14: Renegociación proveedor | H14: =IFERROR(IF(OR(E14="",F14="",G14=""),0,ROUND((E14+4*F14+G14)/6,0)),0) -> 0 | I14: =H14*12 -> 0 | K14: =IFERROR(IF(AND(H14>0,J14>0),ROUND(J14/H14,1),"-"),"-") -> - | L14: =IFERROR(IF(J14>0,(I14-J14)/J14,""),"") | M14: Propuesta
A15: 5 | B15: Almacén de repuestos · pan de bonos · aerobuses · alianzas | C15: INGRESO | D15: Nueva fuente ingreso | H15: =IFERROR(IF(OR(E15="",F15="",G15=""),0,ROUND((E15+4*F15+G15)/6,0)),0) -> 0 | I15: =H15*12 -> 0 | K15: =IFERROR(IF(AND(H15>0,J15>0),ROUND(J15/H15,1),"-"),"-") -> - | L15: =IFERROR(IF(J15>0,(I15-J15)/J15,""),"") | M15: Propuesta
A16: 6 | H16: =IFERROR(IF(OR(E16="",F16="",G16=""),0,ROUND((E16+4*F16+G16)/6,0)),0) -> 0 | I16: =H16*12 -> 0 | K16: =IFERROR(IF(AND(H16>0,J16>0),ROUND(J16/H16,1),"-"),"-") -> - | L16: =IFERROR(IF(J16>0,(I16-J16)/J16,""),"")
A17: 7 | H17: =IFERROR(IF(OR(E17="",F17="",G17=""),0,ROUND((E17+4*F17+G17)/6,0)),0) -> 0 | I17: =H17*12 -> 0 | K17: =IFERROR(IF(AND(H17>0,J17>0),ROUND(J17/H17,1),"-"),"-") -> - | L17: =IFERROR(IF(J17>0,(I17-J17)/J17,""),"")
A18: 8 | H18: =IFERROR(IF(OR(E18="",F18="",G18=""),0,ROUND((E18+4*F18+G18)/6,0)),0) -> 0 | I18: =H18*12 -> 0 | K18: =IFERROR(IF(AND(H18>0,J18>0),ROUND(J18/H18,1),"-"),"-") -> - | L18: =IFERROR(IF(J18>0,(I18-J18)/J18,""),"")
A19: 9 | H19: =IFERROR(IF(OR(E19="",F19="",G19=""),0,ROUND((E19+4*F19+G19)/6,0)),0) -> 0 | I19: =H19*12 -> 0 | K19: =IFERROR(IF(AND(H19>0,J19>0),ROUND(J19/H19,1),"-"),"-") -> - | L19: =IFERROR(IF(J19>0,(I19-J19)/J19,""),"")
A20: 10 | H20: =IFERROR(IF(OR(E20="",F20="",G20=""),0,ROUND((E20+4*F20+G20)/6,0)),0) -> 0 | I20: =H20*12 -> 0 | K20: =IFERROR(IF(AND(H20>0,J20>0),ROUND(J20/H20,1),"-"),"-") -> - | L20: =IFERROR(IF(J20>0,(I20-J20)/J20,""),"")
A21: 11 | H21: =IFERROR(IF(OR(E21="",F21="",G21=""),0,ROUND((E21+4*F21+G21)/6,0)),0) -> 0 | I21: =H21*12 -> 0 | K21: =IFERROR(IF(AND(H21>0,J21>0),ROUND(J21/H21,1),"-"),"-") -> - | L21: =IFERROR(IF(J21>0,(I21-J21)/J21,""),"")
A22: 12 | H22: =IFERROR(IF(OR(E22="",F22="",G22=""),0,ROUND((E22+4*F22+G22)/6,0)),0) -> 0 | I22: =H22*12 -> 0 | K22: =IFERROR(IF(AND(H22>0,J22>0),ROUND(J22/H22,1),"-"),"-") -> - | L22: =IFERROR(IF(J22>0,(I22-J22)/J22,""),"")
A23: 13 | H23: =IFERROR(IF(OR(E23="",F23="",G23=""),0,ROUND((E23+4*F23+G23)/6,0)),0) -> 0 | I23: =H23*12 -> 0 | K23: =IFERROR(IF(AND(H23>0,J23>0),ROUND(J23/H23,1),"-"),"-") -> - | L23: =IFERROR(IF(J23>0,(I23-J23)/J23,""),"")
A24: 14 | H24: =IFERROR(IF(OR(E24="",F24="",G24=""),0,ROUND((E24+4*F24+G24)/6,0)),0) -> 0 | I24: =H24*12 -> 0 | K24: =IFERROR(IF(AND(H24>0,J24>0),ROUND(J24/H24,1),"-"),"-") -> - | L24: =IFERROR(IF(J24>0,(I24-J24)/J24,""),"")
A25: 15 | H25: =IFERROR(IF(OR(E25="",F25="",G25=""),0,ROUND((E25+4*F25+G25)/6,0)),0) -> 0 | I25: =H25*12 -> 0 | K25: =IFERROR(IF(AND(H25>0,J25>0),ROUND(J25/H25,1),"-"),"-") -> - | L25: =IFERROR(IF(J25>0,(I25-J25)/J25,""),"")
A26: TOTAL DEPARTAMENTO | E26: =SUM(E11:E25) -> 0 | F26: =SUM(F11:F25) -> 0 | G26: =SUM(G11:G25) -> 0 | H26: =SUM(H11:H25) -> 0 | I26: =SUM(I11:I25) -> 0 | J26: =SUM(J11:J25) -> 0
A28: 3. PLAN DE IMPLEMENTACIÓN · HITOS PRINCIPALES
A29: # | B29: Hito / acción | H29: Responsable | K29: Fecha objetivo | M29: Estado
A30: 1
A31: 2
A32: 3
A33: 4
A34: 5
A35: 6
A37: 4. KPIs DE SEGUIMIENTO MENSUAL
A38: KPI | F38: Línea base | I38: Meta mensual | L38: Frecuencia
A39: Accidentalidad (eventos/mes) | L39: Mensual
A40: Rotación de personal | L40: Mensual
A41: Ausentismo de conductores | L41: Mensual
A42: Conductores tarde | L42: Mensual
A43: Ahorro materializado vs. proyectado | L43: Mensual
A48: 5. COMPROMISO Y FIRMA
...

Sheet Tecnología (TI)
A1: LA CAROLINA · METROPOLITANA DE TRANSPORTE
A2: DEPARTAMENTO: TECNOLOGÍA (TI)
A3: Plantilla de iniciativas de ahorro e ingreso · Comité Directivos · 26 may 2026
A5: 1. DATOS DEL JEFE Y ENTREGA
A6: Jefe responsable | D6: Fecha entrega | G6: # Iniciativas | I6: Total ahorro/ingreso anual
G7: =COUNTA(B11:B25) -> 7 | I7: =SUM(I11:I25) -> 41686134
A9: 2. INICIATIVAS · LLENE LAS CELDAS AMARILLAS
A10: # | B10: Iniciativa | C10: Tipo | D10: Categoría | E10: Pesim. mes | F10: Base mes | G10: Optim. mes | H10: Esperado mes | I10: Anual esperado | J10: CapEx | K10: Payback (m) | L10: ROI 12m | M10: Estado | N10: Notas / Metodología
A11: 1 | B11: Renegociar LM Solución — objetivo ahorro 20-30% (gasto ~$128M/año) | C11: AHORRO | D11: Renegociación proveedor | E11: 6000000 | F11: 6000000 | G11: 6000000 | H11: =IFERROR(IF(OR(E11="",F11="",G11=""),0,ROUND((E11+4*F11+G11)/6,0)),0) -> 6000000 | I11: =(H11*12)/2 -> 36000000 | K11: =IFERROR(IF(AND(H11>0,J11>0),ROUND(J11/H11,1),"-"),"-") -> - | L11: =IFERROR(IF(J11>0,(I11-J11)/J11,""),"") | M11: Negociación | N11: Varia la cotizacion debido a que ellos no colocan el gps
A12: 2 | B12: Plan repotenciación de equipos (vida útil +2-3 años, ahorro 15-20%) | C12: AHORRO | D12: Optimización proceso | H12: =IFERROR(IF(OR(E12="",F12="",G12=""),0,ROUND((E12+4*F12+G12)/6,0)),0) -> 0 | I12: =H12*12 -> 0 | K12: =IFERROR(IF(AND(H12>0,J12>0),ROUND(J12/H12,1),"-"),"-") -> - | L12: =IFERROR(IF(J12>0,(I12-J12)/J12,""),"") | M12: Propuesta | N12: En Revision Debido a verificacio de repotenciacion de equipos y años de usoso posibles y tecnologia actual
A13: 3 | B13: Aplicativo de alertas de repuestos repetitivos (con Mantenimiento) | C13: AHORRO | D13: Tecnología | H13: =IFERROR(IF(OR(E13="",F13="",G13=""),0,ROUND((E13+4*F13+G13)/6,0)),0) -> 0 | I13: =H13*12 -> 0 | K13: =IFERROR(IF(AND(H13>0,J13>0),ROUND(J13/H13,1),"-"),"-") -> - | L13: =IFERROR(IF(J13>0,(I13-J13)/J13,""),"") | M13: Por desarrollar | N13: Plan SAAS
A14: 4 | B14: Plataforma de control interno Carolina S.A.S — repositorio + anotaciones + data | C14: AHORRO | D14: Tecnología | H14: =IFERROR(IF(OR(E14="",F14="",G14=""),0,ROUND((E14+4*F14+G14)/6,0)),0) -> 0 | I14: =H14*12 -> 0 | K14: =IFERROR(IF(AND(H14>0,J14>0),ROUND(J14/H14,1),"-"),"-") -> - | L14: =IFERROR(IF(J14>0,(I14-J14)/J14,""),"") | M14: Por desarrollar | N14: Plan SAAS
A15: 5 | B15: App Carolina S.A.S — reporte taller + accidentalidad (piloto 8 días) | C15: MIXTA | D15: Tecnología | H15: =IFERROR(IF(OR(E15="",F15="",G15=""),0,ROUND((E15+4*F15+G15)/6,0)),0) -> 0 | I15: =H15*12 -> 0 | K15: =IFERROR(IF(AND(H15>0,J15>0),ROUND(J15/H15,1),"-"),"-") -> - | L15: =IFERROR(IF(J15>0,(I15-J15)/J15,""),"") | M15: Piloto | N15: Plan SAAS
A16: 6 | B16: Automatización WhatsApp con app Víctor (~$0.03 USD/conexión) | C16: AHORRO | D16: Tecnología | H16: =IFERROR(IF(OR(E16="",F16="",G16=""),0,ROUND((E16+4*F16+G16)/6,0)),0) -> 0 | I16: =H16*12 -> 0 | K16: =IFERROR(IF(AND(H16>0,J16>0),ROUND(J16/H16,1),"-"),"-") -> - | L16: =IFERROR(IF(J16>0,(I16-J16)/J16,""),"") | M16: Propuesta | N16: Plan SAAS
A17: 7 | B17: Gestion Llantas Pro (Control interno) | C17: AHORRO | D17: Tecnología | E17: 947689 | F17: 947689 | G17: 947689 | H17: =IFERROR(IF(OR(E17="",F17="",G17=""),0,ROUND((E17+4*F17+G17)/6,0)),0) -> 947689 | I17: =(H17*12)/2 -> 5686134 | K17: =IFERROR(IF(AND(H17>0,J17>0),ROUND(J17/H17,1),"-"),"-") -> - | L17: =IFERROR(IF(J17>0,(I17-J17)/J17,""),"") | M17: En curso | N17: Implementado apartir de abril del 2026
A18: 8 | H18: =IFERROR(IF(OR(E18="",F18="",G18=""),0,ROUND((E18+4*F18+G18)/6,0)),0) -> 0 | I18: =H18*12 -> 0 | K18: =IFERROR(IF(AND(H18>0,J18>0),ROUND(J18/H18,1),"-"),"-") -> - | L18: =IFERROR(IF(J18>0,(I18-J18)/J18,""),"")
A19: 9 | H19: =IFERROR(IF(OR(E19="",F19="",G19=""),0,ROUND((E19+4*F19+G19)/6,0)),0) -> 0 | I19: =H19*12 -> 0 | K19: =IFERROR(IF(AND(H19>0,J19>0),ROUND(J19/H19,1),"-"),"-") -> - | L19: =IFERROR(IF(J19>0,(I19-J19)/J19,""),"")
A20: 10 | H20: =IFERROR(IF(OR(E20="",F20="",G20=""),0,ROUND((E20+4*F20+G20)/6,0)),0) -> 0 | I20: =H20*12 -> 0 | K20: =IFERROR(IF(AND(H20>0,J20>0),ROUND(J20/H20,1),"-"),"-") -> - | L20: =IFERROR(IF(J20>0,(I20-J20)/J20,""),"")
A21: 11 | H21: =IFERROR(IF(OR(E21="",F21="",G21=""),0,ROUND((E21+4*F21+G21)/6,0)),0) -> 0 | I21: =H21*12 -> 0 | K21: =IFERROR(IF(AND(H21>0,J21>0),ROUND(J21/H21,1),"-"),"-") -> - | L21: =IFERROR(IF(J21>0,(I21-J21)/J21,""),"")
A22: 12 | H22: =IFERROR(IF(OR(E22="",F22="",G22=""),0,ROUND((E22+4*F22+G22)/6,0)),0) -> 0 | I22: =H22*12 -> 0 | K22: =IFERROR(IF(AND(H22>0,J22>0),ROUND(J22/H22,1),"-"),"-") -> - | L22: =IFERROR(IF(J22>0,(I22-J22)/J22,""),"")
A23: 13 | H23: =IFERROR(IF(OR(E23="",F23="",G23=""),0,ROUND((E23+4*F23+G23)/6,0)),0) -> 0 | I23: =H23*12 -> 0 | K23: =IFERROR(IF(AND(H23>0,J23>0),ROUND(J23/H23,1),"-"),"-") -> - | L23: =IFERROR(IF(J23>0,(I23-J23)/J23,""),"")
A24: 14 | H24: =IFERROR(IF(OR(E24="",F24="",G24=""),0,ROUND((E24+4*F24+G24)/6,0)),0) -> 0 | I24: =H24*12 -> 0 | K24: =IFERROR(IF(AND(H24>0,J24>0),ROUND(J24/H24,1),"-"),"-") -> - | L24: =IFERROR(IF(J24>0,(I24-J24)/J24,""),"")
A25: 15 | H25: =IFERROR(IF(OR(E25="",F25="",G25=""),0,ROUND((E25+4*F25+G25)/6,0)),0) -> 0 | I25: =H25*12 -> 0 | K25: =IFERROR(IF(AND(H25>0,J25>0),ROUND(J25/H25,1),"-"),"-") -> - | L25: =IFERROR(IF(J25>0,(I25-J25)/J25,""),"")
A26: TOTAL DEPARTAMENTO | E26: =SUM(E11:E25) -> 6947689 | F26: =SUM(F11:F25) -> 6947689 | G26: =SUM(G11:G25) -> 6947689 | H26: =SUM(H11:H25) -> 6947689 | I26: =SUM(I11:I25) -> 41686134 | J26: =SUM(J11:J25) -> 0
A28: 3. PLAN DE IMPLEMENTACIÓN · HITOS PRINCIPALES
A29: # | B29: Hito / acción | H29: Responsable | K29: Fecha objetivo | M29: Estado
A30: 1
A31: 2
A32: 3
A33: 4
A34: 5
A35: 6
A37: 4. KPIs DE SEGUIMIENTO MENSUAL
A38: KPI | F38: Línea base | I38: Meta mensual | L38: Frecuencia
A39: Accidentalidad (eventos/mes) | L39: Mensual
A40: Rotación de personal | L40: Mensual
A41: Ausentismo de conductores | L41: Mensual
A42: Conductores tarde | L42: Mensual
A43: Ahorro materializado vs. proyectado | L43: Mensual
A48: 5. COMPROMISO Y FIRMA
...

Sheet Talento Humano
A1: LA CAROLINA · METROPOLITANA DE TRANSPORTE
A2: DEPARTAMENTO: TALENTO HUMANO
A3: Plantilla de iniciativas de ahorro e ingreso · Comité Directivos · 26 may 2026
A5: 1. DATOS DEL JEFE Y ENTREGA
A6: Jefe responsable | D6: Fecha entrega | G6: # Iniciativas | I6: Total ahorro/ingreso anual
G7: =COUNTA(B11:B20) -> 4 | I7: =SUM(I11:I20) -> 55792578
A9: 2. INICIATIVAS · LLENE LAS CELDAS AMARILLAS
A10: # | B10: Iniciativa | C10: Tipo | D10: Categoría | E10: Pesim. mes | F10: Base mes | G10: Optim. mes | H10: Esperado mes | I10: Anual esperado | J10: CapEx | K10: Payback (m) | L10: ROI 12m | M10: Estado | N10: Notas / Metodología
A11: 1 | B11: Cambio proveedor polígrafo (Comfamiliar más económico) | C11: AHORRO | D11: Reducción consumo | E11: 440000 | F11: 440000 | G11: 440000 | H11: =IFERROR(IF(OR(E11="",F11="",G11=""),0,ROUND((E11+4*F11+G11)/6,0)),0) -> 440000 | I11: =H11*6 -> 2640000 | K11: =IFERROR(IF(AND(H11>0,J11>0),ROUND(J11/H11,1),"-"),"-") -> - | L11: =IFERROR(IF(J11>0,(I11-J11)/J11,""),"") | M11: Propuesta | N11: Con base en el promedio calculado de 3,67 poligrafias/mes: Mensual: 3,67 × $120.000 = $440.000 Anual: $440.000 × 12 = $5.280.000
A12: 2 | B12: Reubicación de aprendices para reemplazar cargos fijos | C12: AHORRO | D12: Optimización proceso | E12: 2715430 | F12: 2715430 | G12: 2715430 | H12: =IFERROR(IF(OR(E12="",F12="",G12=""),0,ROUND((E12+4*F12+G12)/6,0)),0) -> 2715430 | I12: =H12*6 -> 16292580 | K12: =IFERROR(IF(AND(H12>0,J12>0),ROUND(J12/H12,1),"-"),"-") -> - | L12: =IFERROR(IF(J12>0,(I12-J12)/J12,""),"") | M12: Propuesta | N12: el aprendiz puede reemplazar un cargo fijo que se pueda realizar cada 6 meses con rotacion de aprendices
A13: 3 | B13: Reducción de actividades de bienestar: DÍA DEL PADRE DÍA DE AMOR Y AMISTAD ENTREGA DE OBSEQUIOS FIN DE AÑO (HIJOS) NOVENA NAVIDEÑA INTEGRACIÓN ADMINISTRATIVA FIN DE AÑO | C13: AHORRO | E13: 2783333 | F13: 2783333 | G13: 2783333 | H13: =IFERROR(IF(OR(E13="",F13="",G13=""),0,ROUND((E13+4*F13+G13)/6,0)),0) -> 2783333 | I13: =H13*6 -> 16699998 | K13: =IFERROR(IF(AND(H13>0,J13>0),ROUND(J13/H13,1),"-"),"-") -> - | L13: =IFERROR(IF(J13>0,(I13-J13)/J13,""),"") | M13: Propuesta | N13: Promedio por mes $2.783.333 correspondiente a los 6 meses que faltan del año DÍA DEL PADRE: $2.500.000 DÍA DE AMOR Y AMISTAD: $3.000.000 ENTREGA DE OBSEQUIOS FIN DE AÑO (HIJOS): $4.000.000 NOVENA NAVIDEÑA: $2.700.000 INTEGRACIÓN ADMINISTRATIVA FIN DE AÑO $4.500.000
A14: 9 | B14: RECUPERACION EN EXAMENES MEDICOS DE INGRESO | C14: MIXTA | D14: Nueva fuente ingreso | E14: 3360000 | F14: 3360000 | G14: 3360000 | H14: =IFERROR(IF(OR(E14="",F14="",G14=""),0,ROUND((E14+4*F14+G14)/6,0)),0) -> 3360000 | I14: =H14*6 -> 20160000 | K14: =IFERROR(IF(AND(H14>0,J14>0),ROUND(J14/H14,1),"-"),"-") -> - | L14: =IFERROR(IF(J14>0,(I14-J14)/J14,""),"") | N14: PROMEDIO MENSUAL DE INGRESOS POR MES (14) SEGUN LOS ULTIMOS 7 MESES
A15: 10 | H15: =IFERROR(IF(OR(E15="",F15="",G15=""),0,ROUND((E15+4*F15+G15)/6,0)),0) -> 0 | I15: =H15*12 -> 0 | K15: =IFERROR(IF(AND(H15>0,J15>0),ROUND(J15/H15,1),"-"),"-") -> - | L15: =IFERROR(IF(J15>0,(I15-J15)/J15,""),"")
A16: 11 | H16: =IFERROR(IF(OR(E16="",F16="",G16=""),0,ROUND((E16+4*F16+G16)/6,0)),0) -> 0 | I16: =H16*12 -> 0 | K16: =IFERROR(IF(AND(H16>0,J16>0),ROUND(J16/H16,1),"-"),"-") -> - | L16: =IFERROR(IF(J16>0,(I16-J16)/J16,""),"")
A17: 12 | H17: =IFERROR(IF(OR(E17="",F17="",G17=""),0,ROUND((E17+4*F17+G17)/6,0)),0) -> 0 | I17: =H17*12 -> 0 | K17: =IFERROR(IF(AND(H17>0,J17>0),ROUND(J17/H17,1),"-"),"-") -> - | L17: =IFERROR(IF(J17>0,(I17-J17)/J17,""),"")
A18: 13 | H18: =IFERROR(IF(OR(E18="",F18="",G18=""),0,ROUND((E18+4*F18+G18)/6,0)),0) -> 0 | I18: =H18*12 -> 0 | K18: =IFERROR(IF(AND(H18>0,J18>0),ROUND(J18/H18,1),"-"),"-") -> - | L18: =IFERROR(IF(J18>0,(I18-J18)/J18,""),"")
A19: 14 | H19: =IFERROR(IF(OR(E19="",F19="",G19=""),0,ROUND((E19+4*F19+G19)/6,0)),0) -> 0 | I19: =H19*12 -> 0 | K19: =IFERROR(IF(AND(H19>0,J19>0),ROUND(J19/H19,1),"-"),"-") -> - | L19: =IFERROR(IF(J19>0,(I19-J19)/J19,""),"")
A20: 15 | H20: =IFERROR(IF(OR(E20="",F20="",G20=""),0,ROUND((E20+4*F20+G20)/6,0)),0) -> 0 | I20: =H20*12 -> 0 | K20: =IFERROR(IF(AND(H20>0,J20>0),ROUND(J20/H20,1),"-"),"-") -> - | L20: =IFERROR(IF(J20>0,(I20-J20)/J20,""),"")
A21: TOTAL DEPARTAMENTO | E21: =SUM(E11:E20) -> 9298763 | F21: =SUM(F11:F20) -> 9298763 | G21: =SUM(G11:G20) -> 9298763 | H21: =SUM(H11:H20) -> 9298763 | I21: =SUM(I11:I20) -> 55792578 | J21: =SUM(J11:J20) -> 0
A23: 3. PLAN DE IMPLEMENTACIÓN · HITOS PRINCIPALES
A24: # | B24: Hito / acción | H24: Responsable | K24: Fecha objetivo | M24: Estado
A25: 1
A26: 2
A27: 3
A28: 4
A29: 5
A30: 6
A32: 4. KPIs DE SEGUIMIENTO MENSUAL
A33: KPI | F33: Línea base | I33: Meta mensual | L33: Frecuencia
A34: Accidentalidad (eventos/mes) | L34: Mensual
A35: Rotación de personal | L35: Mensual
A36: Ausentismo de conductores | L36: Mensual
A37: Conductores tarde | L37: Mensual
A38: Ahorro materializado vs. proyectado | L38: Mensual
A43: 5. COMPROMISO Y FIRMA
A44: Yo, jefe de Talento Humano, me comprometo a ejecutar las iniciativas descritas, reportar avances en cada comité directivo y materializar el ahorro/ingreso proyectado durante el año fiscal 2026.
A47: Firma Jefe de Departamento | H47: Aprobado Dirección General — Liliana Anaya CEO
A49: TRANSPORTE CON CORAZÓN · Ideas ejecutables · Planes medibles

Sheet CONSOLIDADO
A1: CONSOLIDADO POR DEPARTAMENTO · LA CAROLINA 2026
A2: Vista para Dirección General · Cifras se actualizan automáticamente al diligenciar cada hoja
A4: # | B4: DEPARTAMENTO | C4: JEFE RESPONSABLE | D4: # INICIATIVAS | E4: AHORRO/INGRESO MES | F4: ANUAL ESPERADO | G4: CAPEX TOTAL | H4: ESTADO
A5: 1 | B5: Tesorería | C5: =Tesorería!A7 -> 0 | D5: =COUNTA(Tesorería!B11:B25) -> 4 | E5: =SUM(Tesorería!H11:H25) -> 5482000 | F5: =SUM(Tesorería!I11:I25) -> 38374000 | G5: =SUM(Tesorería!J11:J25) -> 0 | H5: =COUNTA(Tesorería!M11:M25)&" registros" -> 4 registros
A6: 2 | B6: Contabilidad | C6: =Contabilidad!A7 -> 0 | D6: =COUNTA(Contabilidad!B11:B25) -> 7 | E6: =SUM(Contabilidad!H11:H25) -> 6306533 | F6: =SUM(Contabilidad!I11:I25) -> 75678396 | G6: =SUM(Contabilidad!J11:J25) -> 0 | H6: =COUNTA(Contabilidad!M11:M25)&" registros" -> 7 registros
A7: 3 | B7: Mantenimiento y Compras | C7: ='Mantenimiento y Compras'!A7 -> 0 | D7: =COUNTA('Mantenimiento y Compras'!B11:B25) -> 9 | E7: =SUM('Mantenimiento y Compras'!H11:H25) -> 10177243 | F7: =SUM('Mantenimiento y Compras'!I11:I25) -> 74093466 | G7: =SUM('Mantenimiento y Compras'!J11:J25) -> 0 | H7: =COUNTA('Mantenimiento y Compras'!M11:M25)&" registros" -> 9 registros
A8: 4 | B8: Operaciones | C8: =Operaciones!A7 -> 0 | D8: =COUNTA(Operaciones!B11:B25) -> 5 | E8: =SUM(Operaciones!H11:H25) -> 25101500 | F8: =SUM(Operaciones!I11:I25) -> 301218000 | G8: =SUM(Operaciones!J11:J25) -> 0 | H8: =COUNTA(Operaciones!M11:M25)&" registros" -> 5 registros
A9: 5 | B9: Comercial | C9: =Comercial!A7 -> 0 | D9: =COUNTA(Comercial!B11:B25) -> 5 | E9: =SUM(Comercial!H11:H25) -> 0 | F9: =SUM(Comercial!I11:I25) -> 0 | G9: =SUM(Comercial!J11:J25) -> 0 | H9: =COUNTA(Comercial!M11:M25)&" registros" -> 5 registros
A10: 6 | B10: Tecnología (TI) | C10: ='Tecnología (TI)'!A7 -> 0 | D10: =COUNTA('Tecnología (TI)'!B11:B25) -> 7 | E10: =SUM('Tecnología (TI)'!H11:H25) -> 6947689 | F10: =SUM('Tecnología (TI)'!I11:I25) -> 41686134 | G10: =SUM('Tecnología (TI)'!J11:J25) -> 0 | H10: =COUNTA('Tecnología (TI)'!M11:M25)&" registros" -> 7 registros
A11: 7 | B11: Talento Humano | C11: ='Talento Humano'!A7 -> 0 | D11: =COUNTA('Talento Humano'!B11:B20) -> 4 | E11: =SUM('Talento Humano'!H11:H20) -> 9298763 | F11: =SUM('Talento Humano'!I11:I20) -> 55792578 | G11: =SUM('Talento Humano'!J11:J20) -> 0 | H11: =COUNTA('Talento Humano'!M11:M20)&" registros" -> 3 registros
A12: TOTAL CONSOLIDADO LA CAROLINA | D12: =SUM(D5:D11) -> 41 | E12: =SUM(E5:E11) -> 63313728 | F12: =SUM(F5:F11) -> 586842574 | G12: =SUM(G5:G11) -> 0
A14: TRANSPORTE CON CORAZÓN · Movemos el progreso de Barranquilla
